{"uuid": "802bd37d-1b24-426b-8c73-2f8761e24f82", "children": ["6230768c-4341-41b6-9b6e-60f16c6c2510", "808ca80e-c1c8-4295-b00f-8ea9e1f612b6", "e4123454-95bb-43b5-8be1-02cfb4f68064", "e6cb0970-5c53-48af-8bae-55d4a8a41f88", "3675390a-abd4-4968-af93-66bf51a9313a"], "befores": [{"name": "delete_all_lesson", "status": "broken", "statusDetails": {"message": "requests.exceptions.ConnectionError: HTTPConnectionPool(host='127.0.0.1', port=80): Max retries exceeded with url: /api/mgr/loginReq (Caused by NewConnectionError('<urllib3.connection.HTTPConnection object at 0x04CEECD0>: Failed to establish a new connection: [WinError 10061] 由于目标计算机积极拒绝，无法连接。',))\n", "trace": "  File \"g:\\program files (x86)\\python36-32\\lib\\site-packages\\pluggy\\callers.py\", line 187, in _multicall\n    res = hook_impl.function(*args)\n  File \"g:\\program files (x86)\\python36-32\\lib\\site-packages\\_pytest\\fixtures.py\", line 1124, in pytest_fixture_setup\n    result = call_fixture_func(fixturefunc, request, kwargs)\n  File \"g:\\program files (x86)\\python36-32\\lib\\site-packages\\_pytest\\fixtures.py\", line 930, in call_fixture_func\n    fixture_result = fixturefunc(**kwargs)\n  File \"G:\\PycharmProjects\\teach\\testCaseTeach\\conftest.py\", line 13, in delete_all_lesson\n    session =LoginClass().api_login('{\"username\":\"auto\",\"password\":\"sdfsdfsdf\"}',getSession =True)#getSession =True缺省\n  File \"G:\\PycharmProjects\\teach\\Lib\\ApiLogin.py\", line 14, in api_login\n    reps = requests.post(api_url, data=payload)\n  File \"g:\\program files (x86)\\python36-32\\lib\\site-packages\\requests\\api.py\", line 119, in post\n    return request('post', url, data=data, json=json, **kwargs)\n  File \"g:\\program files (x86)\\python36-32\\lib\\site-packages\\requests\\api.py\", line 61, in request\n    return session.request(method=method, url=url, **kwargs)\n  File \"g:\\program files (x86)\\python36-32\\lib\\site-packages\\requests\\sessions.py\", line 530, in request\n    resp = self.send(prep, **send_kwargs)\n  File \"g:\\program files (x86)\\python36-32\\lib\\site-packages\\requests\\sessions.py\", line 643, in send\n    r = adapter.send(request, **kwargs)\n  File \"g:\\program files (x86)\\python36-32\\lib\\site-packages\\requests\\adapters.py\", line 516, in send\n    raise ConnectionError(e, request=request)\n"}, "start": 1605192030720, "stop": 1605192032725}], "start": 1605192030720, "stop": 1605192033604}