{"uuid": "c685eaf0-f3dc-410b-ab5a-07e84ad12677", "children": ["2e2c3919-b2ac-41db-918d-0401e833a432", "efa265c0-b649-434f-afca-487fed62fe67", "cc271e45-191f-4832-8b05-7ffd6d964d72", "5025c0d7-59d8-4e73-b150-7fb07e72a264", "9bdf9f8d-6704-4302-b3c6-87188a27f1e4"], "befores": [{"name": "delete_all_lesson", "status": "broken", "statusDetails": {"message": "requests.exceptions.ConnectionError: HTTPConnectionPool(host='127.0.0.1', port=80): Max retries exceeded with url: /api/mgr/loginReq (Caused by NewConnectionError('<urllib3.connection.HTTPConnection object at 0x0444FDD0>: Failed to establish a new connection: [WinError 10061] 由于目标计算机积极拒绝，无法连接。',))\n", "trace": "  File \"g:\\program files (x86)\\python36-32\\lib\\site-packages\\pluggy\\callers.py\", line 187, in _multicall\n    res = hook_impl.function(*args)\n  File \"g:\\program files (x86)\\python36-32\\lib\\site-packages\\_pytest\\fixtures.py\", line 1124, in pytest_fixture_setup\n    result = call_fixture_func(fixturefunc, request, kwargs)\n  File \"g:\\program files (x86)\\python36-32\\lib\\site-packages\\_pytest\\fixtures.py\", line 930, in call_fixture_func\n    fixture_result = fixturefunc(**kwargs)\n  File \"G:\\PycharmProjects\\teach\\testCaseTeach\\conftest.py\", line 13, in delete_all_lesson\n    session =LoginClass().api_login('{\"username\":\"auto\",\"password\":\"sdfsdfsdf\"}',getSession =True)#getSession =True缺省\n  File \"G:\\PycharmProjects\\teach\\Lib\\ApiLogin.py\", line 14, in api_login\n    reps = requests.post(api_url, data=payload)\n  File \"g:\\program files (x86)\\python36-32\\lib\\site-packages\\requests\\api.py\", line 119, in post\n    return request('post', url, data=data, json=json, **kwargs)\n  File \"g:\\program files (x86)\\python36-32\\lib\\site-packages\\requests\\api.py\", line 61, in request\n    return session.request(method=method, url=url, **kwargs)\n  File \"g:\\program files (x86)\\python36-32\\lib\\site-packages\\requests\\sessions.py\", line 530, in request\n    resp = self.send(prep, **send_kwargs)\n  File \"g:\\program files (x86)\\python36-32\\lib\\site-packages\\requests\\sessions.py\", line 643, in send\n    r = adapter.send(request, **kwargs)\n  File \"g:\\program files (x86)\\python36-32\\lib\\site-packages\\requests\\adapters.py\", line 516, in send\n    raise ConnectionError(e, request=request)\n"}, "start": 1605360699079, "stop": 1605360701085}], "start": 1605360699079, "stop": 1605360702001}